Workbook

Sheet Income
B2: Chinhoyi Apartment tracker
B3: January - December 2020
B4: Income
B6: Year: | C6: 2020 | E6: Total Income | G6: =AI41 -> 17325.541 | J6: Total deposits 2020 | L6: =R24+P24+L24+J24+F24 -> 1125 | N6: Balances owed | O6: =AJ41 -> 325.99885
J8: Total deposits prior | L8: =D24+H24+N24 -> 875
B10: Property Code | C10: Property Address | G10: Tenant Name | I10: Email address | L10: Phone Number | N10: ID number | O10: Move-In Date | P10: Lease expiry
B11: Unit 1 | C11: 458 North Drive CBD Chinhoyi | G11: Campion Chako | I11: chakoc@live.com | L11: 772665333 | O11: 42948 | P11: 44378
B12: Unit 2 | C12: 458 North Drive CBD Chinhoyi | G12: Tafadzwa Maposa | I12: ttmaposa3333@gmail.com | L12: 773626922 | O12: 44075 | P12: 44409
B13: Unit 3 | C13: 458 North Drive CBD Chinhoyi | G13: Linda Ndarangwa | I13: lindandarangwa@gmail.com | L13: 773486504 | O13: 43647 | P13: 44348
B14: Unit 4 | C14: 458 North Drive CBD Chinhoyi | G14: Desire Masango | I14: desiremasango@gmail.com | L14: 774828474 | O14: 44105 | P14: 44440
B15: Unit 5 | C15: 458 North Drive CBD Chinhoyi | G15: Tawanda Maheka | I15: kimropafadzo@gmail.com | L15: 772795939 | O15: 44044 | P15: 44378
B16: Unit 6 | C16: 458 North Drive CBD Chinhoyi | G16: Paul Kembo | I16: pmkembo@gmail.com | L16: 775393827 | O16: 43678 | P16: 44378
B17: Unit 7 | C17: 458 North Drive CBD Chinhoyi | G17: Antonaitte Kaochilima | I17: aaakacholima7@gmail.com | L17: 773388090 | O17: 44044 | P17: 44378
B18: Unit 8 | C18: 458 North Drive CBD Chinhoyi | G18: Clotilder Mukwangariva | I18: cmukwangwariva@gmail.com | L18: 736462688 | O18: 43831 | P18: 44166
B21: Security Deposits | C21: Unit 1 | E21: Unit 2 | G21: Unit 3 | I21: Unit 4 | K21: Unit 5 | M21: Unit 6 | O21: Unit 7 | Q21: Unit 8 | S21: Total
C22: Date | D22: Amount | E22: Date | F22: Amount | G22: Date | H22: Amount | I22: Date | J22: Amount | K22: Date | L22: Amount | M22: Date | N22: Amount | O22: Date | P22: Amount | Q22: Date | R22: Amount | S22: Amount
C23: 42948 | D23: 400 | E23: 44075 | F23: 250 | G23: 43647 | H23: 250 | I23: 44105 | J23: 250 | K23: 44044 | L23: 225 | M23: 43678 | N23: 225 | O23: 44044 | P23: 200 | Q23: 43831 | R23: 200 | S23: =D23+F23+H23+J23+L23+N23+P23+R23 -> 2000
B24: Total | D24: =D23 -> 400 | F24: =F23 -> 250 | H24: =H23 -> 250 | J24: =J23 -> 250 | L24: =L23 -> 225 | N24: =N23 -> 225 | P24: =P23 -> 200 | R24: =R23 -> 200 | S24: =D24+F24+H24+J24+L24+N24+P24+R24 -> 2000
B27: Rental Income | C27: Unit 1 | G27: Unit 2 | K27: Unit 3 | O27: Unit 4 | S27: Unit 5 | W27: Unit 6 | AA27: Unit 7 | AE27: Unit 8 | AI27: Total
C28: Date | D28: Rent due | E28: Amnt paid | F28: Balance | G28: Date | H28: Rent due | I28: Amnt paid | J28: Balance | K28: Date | L28: Rent due | M28: Amnt paid | N28: Balance | O28: Date | P28: Rent due | Q28: Amnt paid | R28: Balance | S28: Date | T28: Rent due | U28: Amnt paid | V28: Balance | W28: Date | X28: Rent due | Y28: Amnt paid | Z28: Balance | AA28: Date | AB28: Rent due | AC28: Amnt paid | AD28: Balance | AE28: Date | AF28: Rent due | AG28: Amnt paid | AH28: Balance | AI28: Rent received | AJ28: Balances owed
B29: January | C29: 25/12/19 | D29: 102.88 | E29: 102.88 | F29: =D29-E29 -> 0 | G29: 25/12/19 | H29: 79.62 | I29: 79.62 | J29: =H29-I29 -> 0 | K29: 25/12/19 | L29: 96.15 | M29: 96.15 | N29: =L29-M29 -> 0 | O29: 25/12/19 | P29: 101.92 | Q29: 101.92 | R29: =P29-Q29 -> 0 | S29: 25/12/19 | T29: 100.96 | U29: 100.96 | V29: =T29-U29 -> 0 | W29: 25/12/19 | X29: =2500/10 -> 250 | Y29: =2500/10 -> 250 | Z29: =X29-Y29 -> 0 | AA29: 25/12/19 | AD29: =AB29-AC29 -> 0 | AE29: 25/12/19 | AF29: 200 | AG29: 200 | AH29: =AF29-AG29 -> 0 | AI29: =E29+I29+M29+Q29+U29+Y29+AC29+AG29 -> 931.53 | AJ29: =F29+J29+N29+R29+V29+Z29+AD29+AH29 -> 0
B30: February | C30: 25/01/20 | D30: 163.46 | E30: 163.46 | F30: =D30-E30 -> 0 | G30: 25/01/20 | H30: 134.62 | I30: 134.62 | J30: =H30-I30 -> 0 | K30: 25/01/20 | L30: 134.62 | M30: 134.62 | N30: =L30-M30 -> 0 | O30: 25/01/20 | P30: 163.46 | Q30: 163.46 | R30: =P30-Q30 -> 0 | S30: 25/01/20 | T30: 163.46 | U30: 163.46 | V30: =T30-U30 -> 0 | W30: 25/01/20 | X30: 147.12 | Y30: 147.12 | Z30: =X30-Y30 -> 0 | AA30: 25/01/20 | AD30: =AB30-AC30 -> 0 | AE30: 25/01/20 | AF30: 200 | AG30: 200 | AH30: =AF30-AG30 -> 0 | AI30: =E30+I30+M30+Q30+U30+Y30+AC30+AG30 -> 1106.74 | AJ30: =F30+J30+N30+R30+V30+Z30+AD30+AH30 -> 0
B31: March | C31: 25/02/20 | D31: 171.63 | E31: 171.63 | F31: =D31-E31 -> 0 | G31: 25/02/20 | H31: 137.31 | I31: 137.31 | J31: =H31-I31 -> 0 | K31: 25/02/20 | L31: 130.77 | M31: 130.77 | N31: =L31-M31 -> 0 | O31: 25/02/20 | P31: 171.63 | Q31: 171.63 | R31: =P31-Q31 -> 0 | S31: 25/02/20 | T31: 171.46 | U31: 171.46 | V31: =T31-U31 -> 0 | W31: 25/02/20 | X31: 155.47 | Y31: =4016.25/26 -> 154.47115 | Z31: =X31-Y31 -> 0.99884615 | AA31: 25/02/20 | AD31: =AB31-AC31 -> 0 | AE31: 25/02/20 | AF31: 200 | AG31: 200 | AH31: =AF31-AG31 -> 0 | AI31: =E31+I31+M31+Q31+U31+Y31+AC31+AG31 -> 1137.2712 | AJ31: =F31+J31+N31+R31+V31+Z31+AD31+AH31 -> 0.99884615
B32: April | C32: 25/03/20 | D32: 250 | E32: 250 | F32: =D32-E32 -> 0 | G32: 25/03/20 | H32: 200 | I32: 200 | J32: =H32-I32 -> 0 | K32: 25/03/20 | L32: 200 | M32: 200 | N32: =L32-M32 -> 0 | O32: 25/03/20 | P32: 250 | Q32: 200 | R32: =P32-Q32 -> 50 | S32: 25/03/20 | T32: 250 | U32: 170 | V32: =T32-U32 -> 80 | W32: 25/03/20 | X32: 225 | Y32: 225 | Z32: =X32-Y32 -> 0 | AA32: 25/03/20 | AD32: =AB32-AC32 -> 0 | AE32: 25/03/20 | AF32: 200 | AG32: 200 | AH32: =AF32-AG32 -> 0 | AI32: =E32+I32+M32+Q32+U32+Y32+AC32+AG32 -> 1445 | AJ32: =F32+J32+N32+R32+V32+Z32+AD32+AH32 -> 130
B33: May | C33: 25/04/20 | D33: 250 | E33: 250 | F33: =D33-E33 -> 0 | G33: 25/04/20 | H33: 200 | I33: 200 | J33: =H33-I33 -> 0 | K33: 25/04/20 | L33: 200 | M33: 200 | N33: =L33-M33 -> 0 | O33: 25/04/20 | P33: 250 | Q33: 180 | R33: =P33-Q33 -> 70 | S33: 25/04/20 | T33: 250 | U33: 180 | V33: =T33-U33 -> 70 | W33: 25/04/20 | X33: 225 | Y33: 225 | Z33: =X33-Y33 -> 0 | AA33: 25/04/20 | AD33: =AB33-AC33 -> 0 | AE33: 25/04/20 | AF33: 200 | AG33: 200 | AH33: =AF33-AG33 -> 0 | AI33: =E33+I33+M33+Q33+U33+Y33+AC33+AG33 -> 1435 | AJ33: =F33+J33+N33+R33+V33+Z33+AD33+AH33 -> 140
B34: June | C34: 25/05/20 | D34: 250 | E34: 250 | F34: =D34-E34 -> 0 | G34: 25/05/20 | H34: 200 | I34: 200 | J34: =H34-I34 -> 0 | K34: 25/05/20 | L34: 200 | M34: 200 | N34: =L34-M34 -> 0 | O34: 25/05/20 | P34: 250 | Q34: 200 | R34: =P34-Q34 -> 50 | S34: 25/05/20 | T34: 250 | U34: 170 | V34: =T34-U34 -> 80 | W34: 25/05/20 | X34: 225 | Y34: 225 | Z34: =X34-Y34 -> 0 | AA34: 25/05/20 | AD34: =AB34-AC34 -> 0 | AE34: 25/05/20 | AF34: 200 | AG34: 200 | AH34: =AF34-AG34 -> 0 | AI34: =E34+I34+M34+Q34+U34+Y34+AC34+AG34 -> 1445 | AJ34: =F34+J34+N34+R34+V34+Z34+AD34+AH34 -> 130
B35: July | C35: 25/06/20 | D35: 250 | E35: 230 | F35: =D35-E35 -> 20 | G35: 25/06/20 | H35: 200 | I35: 200 | J35: =H35-I35 -> 0 | K35: 25/06/20 | L35: 200 | M35: 200 | N35: =L35-M35 -> 0 | O35: 25/06/20 | P35: 250 | Q35: 410 | R35: =P35-Q35 -> -160 | S35: 25/06/20 | V35: =T35-U35 -> 0 | W35: 25/06/20 | X35: 225 | Y35: 225 | Z35: =X35-Y35 -> 0 | AA35: 25/06/20 | AD35: =AB35-AC35 -> 0 | AE35: 25/06/20 | AF35: 200 | AG35: 200 | AH35: =AF35-AG35 -> 0 | AI35: =E35+I35+M35+Q35+U35+Y35+AC35+AG35 -> 1465 | AJ35: =F35+J35+N35+R35+V35+Z35+AD35+AH35 -> -140
B36: August | C36: 25/07/20 | D36: 250 | E36: 250 | F36: =D36-E36 -> 0 | G36: 25/07/20 | J36: =H36-I36 -> 0 | K36: 25/07/20 | L36: 200 | M36: 200 | N36: =L36-M36 -> 0 | O36: 25/07/20 | P36: 250 | Q36: 200 | R36: =P36-Q36 -> 50 | S36: 25/07/20 | T36: 225 | U36: 225 | V36: =T36-U36 -> 0 | W36: 25/07/20 | X36: 225 | Y36: 225 | Z36: =X36-Y36 -> 0 | AA36: 25/07/20 | AB36: 200 | AC36: 200 | AD36: =AB36-AC36 -> 0 | AE36: 25/07/20 | AF36: 200 | AG36: 200 | AH36: =AF36-AG36 -> 0 | AI36: =E36+I36+M36+Q36+U36+Y36+AC36+AG36 -> 1500 | AJ36: =F36+J36+N36+R36+V36+Z36+AD36+AH36 -> 50
B37: September | C37: 25/08/20 | D37: 250 | E37: 230 | F37: =D37-E37 -> 20 | G37: 25/08/20 | H37: 250 | I37: 250 | J37: =H37-I37 -> 0 | K37: 25/08/20 | L37: 200 | M37: 200 | N37: =L37-M37 -> 0 | O37: 25/08/20 | R37: =P37-Q37 -> 0 | S37: 25/08/20 | T37: 225 | U37: 225 | V37: =T37-U37 -> 0 | W37: 25/08/20 | X37: 225 | Y37: 225 | Z37: =X37-Y37 -> 0 | AA37: 25/08/20 | AB37: 200 | AC37: 200 | AD37: =AB37-AC37 -> 0 | AE37: 25/08/20 | AF37: 200 | AG37: 200 | AH37: =AF37-AG37 -> 0 | AI37: =E37+I37+M37+Q37+U37+Y37+AC37+AG37 -> 1530 | AJ37: =F37+J37+N37+R37+V37+Z37+AD37+AH37 -> 20
B38: October | C38: 25/09/20 | D38: 225 | E38: 230 | F38: =D38-E38 -> -5 | G38: 25/09/20 | H38: 250 | I38: 250 | J38: =H38-I38 -> 0 | K38: 25/09/20 | L38: 200 | M38: 200 | N38: =L38-M38 -> 0 | O38: 25/09/20 | P38: 250 | Q38: 250 | R38: =P38-Q38 -> 0 | S38: 25/09/20 | T38: 225 | U38: 225 | V38: =T38-U38 -> 0 | W38: 25/09/20 | X38: 225 | Y38: 225 | Z38: =X38-Y38 -> 0 | AA38: 25/09/20 | AB38: 200 | AC38: 200 | AD38: =AB38-AC38 -> 0 | AE38: 25/09/20 | AF38: 200 | AG38: 200 | AH38: =AF38-AG38 -> 0 | AI38: =E38+I38+M38+Q38+U38+Y38+AC38+AG38 -> 1780 | AJ38: =F38+J38+N38+R38+V38+Z38+AD38+AH38 -> -5
B39: November | C39: 25/10/20 | D39: 225 | E39: 225 | F39: =D39-E39 -> 0 | G39: 25/10/20 | H39: 250 | I39: 250 | J39: =H39-I39 -> 0 | K39: 25/10/20 | L39: 200 | M39: 200 | N39: =L39-M39 -> 0 | O39: 25/10/20 | P39: 250 | Q39: 250 | R39: =P39-Q39 -> 0 | S39: 25/10/20 | T39: 225 | U39: 225 | V39: =T39-U39 -> 0 | W39: 25/10/20 | X39: 225 | Y39: 225 | Z39: =X39-Y39 -> 0 | AA39: 25/10/20 | AB39: 200 | AC39: 200 | AD39: =AB39-AC39 -> 0 | AE39: 25/10/20 | AF39: 200 | AG39: 200 | AH39: =AF39-AG39 -> 0 | AI39: =E39+I39+M39+Q39+U39+Y39+AC39+AG39 -> 1775 | AJ39: =F39+J39+N39+R39+V39+Z39+AD39+AH39 -> 0
B40: December | D40: 225 | E40: 225 | F40: =D40-E40 -> 0 | H40: 250 | I40: 250 | J40: =H40-I40 -> 0 | L40: 200 | M40: 200 | N40: =L40-M40 -> 0 | P40: 250 | Q40: 250 | R40: =P40-Q40 -> 0 | T40: 225 | U40: 225 | V40: =T40-U40 -> 0 | X40: 225 | Y40: 225 | Z40: =X40-Y40 -> 0 | AB40: 200 | AC40: 200 | AD40: =AB40-AC40 -> 0 | AF40: 200 | AG40: 200 | AH40: =AF40-AG40 -> 0 | AI40: =E40+I40+M40+Q40+U40+Y40+AC40+AG40 -> 1775 | AJ40: =F40+J40+N40+R40+V40+Z40+AD40+AH40 -> 0
B41: Total: | D41: =SUM(D29:D40) -> 2612.97 | E41: =SUM(E29:E40) -> 2577.97 | F41: =SUM(F29:F40) -> 35 | H41: =SUM(H29:H40) -> 2151.55 | I41: =SUM(I29:I40) -> 2151.55 | J41: =SUM(J29:J40) -> 0 | L41: =SUM(L29:L40) -> 2161.54 | M41: =SUM(M29:M40) -> 2161.54 | N41: =SUM(N29:N40) -> 0 | P41: =SUM(P29:P40) -> 2437.01 | Q41: =SUM(Q29:Q40) -> 2377.01 | R41: =SUM(R29:R40) -> 60 | T41: =SUM(T29:T40) -> 2310.88 | U41: =SUM(U29:U40) -> 2080.88 | V41: =SUM(V29:V40) -> 230 | X41: =SUM(X29:X40) -> 2577.59 | Y41: =SUM(Y29:Y40) -> 2576.5912 | Z41: =SUM(Z29:Z40) -> 0.99884615 | AB41: =SUM(AB29:AB40) -> 1000 | AC41: =SUM(AC29:AC40) -> 1000 | AD41: =SUM(AD29:AD40) -> 0 | AF41: =SUM(AF29:AF40) -> 2400 | AG41: =SUM(AG29:AG40) -> 2400 | AH41: =SUM(AH29:AH40) -> 0 | AI41: =SUM(AI29:AI40) -> 17325.541 | AJ41: =SUM(AJ29:AJ40) -> 325.99885

Sheet Expenditure
B2: Expenditure
B3: January - December 2020
B5: Period | C5: Date | D5: Category | E5: Amnt | F5: Unit Number | G5: Claiming or not claiming from tenant | H5: Additional notes
B6: January | C6: 02/'01/2020 | D6: Wages & salaries | E6: 100 | G6: Not claiming from tenant | H6: Salary for both Baba Simba and Ncube
D7: Repairs | E7: 54 | H7: Main gate Battery
D8: Other | E8: 28 | G8: Not claiming from tenant | H8: Worksuits
D9: Repairs | E9: 10 | F9: Unit 3 | H9: Flex conncetor fixed
D10: Utilities | E10: 10 | H10: Chinhoyi Council
D11: Withdrawals | E11: 729
E17: =SUM(E6:E16) -> 931
B18: February | D18: Wages & salaries | E18: 100 | H18: Salary for Baba Simba and Ncube
D19: Wages & salaries | E19: 20 | H19: Cleaning fee for Mai Simba
D20: Withdrawals | E20: 787
E27: =SUM(E18:E26) -> 907
B28: March | D28: Wages & salaries | E28: 100 | H28: Salary for Baba Simba and Ncube
D29: Property taxes | E29: 250 | H29: Payment to Itai
D30: Withdrawals | E30: 587
E38: =SUM(E28:E37) -> 937
B39: April | D39: Wages & salaries | E39: 140
D40: Withdrawals | E40: 1105
E48: =SUM(E39:E47) -> 1245
B49: May | D49: Repairs | E49: 70 | F49: Unit 1 | G49: Claiming from tenant | H49: Shower cage replacement
D50: Wages & salaries | E50: 140 | H50: Salary for Ncube and Baba Simba
D51: Repairs | E51: 20 | F51: Unit 1 | G51: Not claiming from tenant | H51: Labour for shower cage
D52: Withdrawals | E52: 1005
E58: =SUM(E49:E57) -> 1235
B59: June | D59: Wages & salaries | E59: 140
D60: Other | E60: 130 | F60: Unit 7 | G60: Not claiming from tenant | H60: clearing flat 7, transport and cleaning
D61: Withdrawals | E61: 975
E68: =SUM(E59:E67) -> 1245
B69: July | D69: Repairs | E69: 475 | F69: Unit 5 | G69: Not claiming from tenant | H69: Repairs to flat 5 and 7
D70: Wages & salaries | E70: 20 | H70: Cleaning fee
D71: Wages & salaries | E71: 200 | H71: Baba Simba and Ncube Salaries
D72: Utilities | E72: 10 | F72: Unit 5 | G72: Not claiming from tenant | H72: ZESA recharge
D73: Withdrawals | E73: 560
E78: =SUM(E69:E77) -> 1265
B79: August | D79: Wages & salaries | E79: 200 | H79: Salaries for Baba Simba and Ncube
D80: Repairs | E80: 285 | H80: Gate change (Material + Labour)
D81: Withdrawals | E81: 1240
E87: =SUM(E79:E86) -> 1725
...

Sheet Income vs Expenditure
B2: Chinhoyi Apartment tracker
B3: January - December 2020
B4: Income vs Expenditure
B6: Income vs expenditure
B7: January 2020 - December 2020
B9: INCOME | C9: ANNUAL | D9: =CONCATENATE("JAN ",$C$2) -> JAN | E9: =CONCATENATE("FEB ",$C$2) -> FEB | F9: =CONCATENATE("MAR ",$C$2) -> MAR | G9: =CONCATENATE("APR ",$C$2) -> APR | H9: =CONCATENATE("MAY ",$C$2) -> MAY | I9: =CONCATENATE("JUN ",$C$2) -> JUN | J9: =CONCATENATE("JUL ",$C$2) -> JUL | K9: =CONCATENATE("AUG ",$C$2) -> AUG | L9: =CONCATENATE("SEP ",$C$2) -> SEP | M9: =CONCATENATE("OCT ",$C$2) -> OCT | N9: =CONCATENATE("NOV ",$C$2) -> NOV | O9: =CONCATENATE("DEC ",$C$2) -> DEC
B10: Unit 1 | C10: =SUM(D10:O10) -> 2577.97 | D10: =Income!E29 -> 102.88 | E10: =Income!E30 -> 163.46 | F10: =Income!E31 -> 171.63 | G10: =Income!E32 -> 250 | H10: =Income!E33 -> 250 | I10: =Income!E34 -> 250 | J10: =Income!E35 -> 230 | K10: =Income!E36 -> 250 | L10: =Income!E37 -> 230 | M10: =Income!E38 -> 230 | N10: =Income!E39 -> 225 | O10: =Income!E40 -> 225
B11: Unit 2 | C11: =SUM(D11:O11) -> 2151.55 | D11: =Income!I29 -> 79.62 | E11: =Income!I30 -> 134.62 | F11: =Income!I31 -> 137.31 | G11: =Income!I32 -> 200 | H11: =Income!I33 -> 200 | I11: =Income!I34 -> 200 | J11: =Income!I35 -> 200 | K11: =Income!I36 | L11: =Income!I37 -> 250 | M11: =Income!I38 -> 250 | N11: =Income!I39 -> 250 | O11: =Income!I40 -> 250
B12: Unit 3 | C12: =SUM(D12:O12) -> 2161.54 | D12: =Income!M29 -> 96.15 | E12: =Income!M30 -> 134.62 | F12: =Income!M31 -> 130.77 | G12: =Income!M32 -> 200 | H12: =Income!M33 -> 200 | I12: =Income!M34 -> 200 | J12: =Income!M35 -> 200 | K12: =Income!M36 -> 200 | L12: =Income!M37 -> 200 | M12: =Income!M38 -> 200 | N12: =Income!M39 -> 200 | O12: =Income!M40 -> 200
B13: Unit 4 | C13: =SUM(D13:O13) -> 2377.01 | D13: =Income!Q29 -> 101.92 | E13: =Income!Q30 -> 163.46 | F13: =Income!Q31 -> 171.63 | G13: =Income!Q32 -> 200 | H13: =Income!Q33 -> 180 | I13: =Income!Q34 -> 200 | J13: =Income!Q35 -> 410 | K13: =Income!Q36 -> 200 | L13: =Income!Q37 | M13: =Income!Q38 -> 250 | N13: =Income!Q39 -> 250 | O13: =Income!Q40 -> 250
B14: Unit 5 | C14: =SUM(D14:O14) -> 2080.88 | D14: =Income!U29 -> 100.96 | E14: =Income!U30 -> 163.46 | F14: =Income!U31 -> 171.46 | G14: =Income!U32 -> 170 | H14: =Income!U33 -> 180 | I14: =Income!U34 -> 170 | J14: =Income!U35 | K14: =Income!U36 -> 225 | L14: =Income!U37 -> 225 | M14: =Income!U38 -> 225 | N14: =Income!U39 -> 225 | O14: =Income!U40 -> 225
B15: Unit 6 | C15: =SUM(D15:O15) -> 2576.5912 | D15: =Income!Y29 -> 250 | E15: =Income!Y30 -> 147.12 | F15: =Income!Y31 -> 154.47115 | G15: =Income!Y32 -> 225 | H15: =Income!Y33 -> 225 | I15: =Income!Y34 -> 225 | J15: =Income!Y35 -> 225 | K15: =Income!Y36 -> 225 | L15: =Income!Y37 -> 225 | M15: =Income!Y38 -> 225 | N15: =Income!Y39 -> 225 | O15: =Income!Y40 -> 225
B16: Unit 7 | C16: =SUM(D16:O16) -> 1000 | D16: =Income!AC29 | E16: =Income!AC30 | F16: =Income!AC31 | G16: =Income!AC32 | H16: =Income!AC33 | I16: =Income!AC34 | J16: =Income!AC35 | K16: =Income!AC36 -> 200 | L16: =Income!AC37 -> 200 | M16: =Income!AC38 -> 200 | N16: =Income!AC39 -> 200 | O16: =Income!AC40 -> 200
B17: Unit 8 | C17: =SUM(D17:O17) -> 2400 | D17: =Income!AG29 -> 200 | E17: =Income!AG30 -> 200 | F17: =Income!AG31 -> 200 | G17: =Income!AG32 -> 200 | H17: =Income!AG33 -> 200 | I17: =Income!AG34 -> 200 | J17: =Income!AG35 -> 200 | K17: =Income!AG36 -> 200 | L17: =Income!AG37 -> 200 | M17: =Income!AG38 -> 200 | N17: =Income!AG39 -> 200 | O17: =Income!AG40 -> 200
B18: TOTAL INCOME | C18: =SUM(C10:C17) -> 17325.541 | D18: =SUM(D10:D16) -> 731.53 | E18: =SUM(E10:E16) -> 906.74 | F18: =SUM(F10:F16) -> 937.27115 | G18: =SUM(G10:G16) -> 1245 | H18: =SUM(H10:H16) -> 1235 | I18: =SUM(I10:I16) -> 1245 | J18: =SUM(J10:J16) -> 1265 | K18: =SUM(K10:K16) -> 1300 | ... N18: =SUM(N10:N16) -> 1575 | O18: =SUM(O10:O17) -> 1775
B20: DEPOSITS 2020 | C20: ANNUAL | D20: =CONCATENATE("JAN ",$C$2) -> JAN | E20: =CONCATENATE("FEB ",$C$2) -> FEB | F20: =CONCATENATE("MAR ",$C$2) -> MAR | G20: =CONCATENATE("APR ",$C$2) -> APR | H20: =CONCATENATE("MAY ",$C$2) -> MAY | I20: =CONCATENATE("JUN ",$C$2) -> JUN | J20: =CONCATENATE("JUL ",$C$2) -> JUL | K20: =CONCATENATE("AUG ",$C$2) -> AUG | L20: =CONCATENATE("SEP ",$C$2) -> SEP | M20: =CONCATENATE("OCT ",$C$2) -> OCT | N20: =CONCATENATE("NOV ",$C$2) -> NOV | O20: =CONCATENATE("DEC ",$C$2) -> DEC
B21: Unit 2 | C21: =SUM(D21:O21) -> 250 | D21: 0 | E21: 0 | F21: 0 | G21: 0 | H21: 0 | I21: 0 | J21: 0 | K21: 0 | L21: 250 | M21: 0 | N21: 0 | O21: 0
B22: Unit 4 | C22: =SUM(D22:O22) -> 250 | D22: 0 | E22: 0 | F22: 0 | G22: 0 | H22: 0 | I22: 0 | J22: 0 | K22: 0 | L22: 0 | M22: 250 | N22: 0 | O22: 0
B23: Unit 5 | C23: =SUM(D23:O23) -> 225 | D23: 0 | E23: 0 | F23: 0 | G23: 0 | H23: 0 | I23: 0 | J23: 0 | K23: 225 | L23: 0 | M23: 0 | N23: 0 | O23: 0
B24: Unit 7 | C24: =SUM(D24:O24) -> 200 | D24: 0 | E24: 0 | F24: 0 | G24: 0 | H24: 0 | I24: 0 | J24: 0 | K24: 200 | L24: 0 | M24: 0 | N24: 0 | O24: 0
B25: Unit 8 | C25: =SUM(D25:O25) -> 200 | D25: 200 | E25: 0 | F25: 0 | G25: 0 | H25: 0 | I25: 0 | J25: 0 | K25: 0 | L25: 0 | M25: 0 | N25: 0 | O25: 0
B26: TOTAL DEPOSITS | C26: =SUM(C21:C25) -> 1125 | D26: =SUM(D21:D25) -> 200 | E26: =SUM(E21:E25) -> 0 | F26: =SUM(F21:F25) -> 0 | G26: =SUM(G21:G25) -> 0 | H26: =SUM(H21:H25) -> 0 | I26: =SUM(I21:I25) -> 0 | J26: =SUM(J21:J25) -> 0 | ... O26: =SUM(O21:O25) -> 0
B28: TOTAL INCOME & DEPOSITS | C28: =C26+C18 -> 18450.541 | D28: =D26+D18 -> 931.53 | E28: =E26+E18 -> 906.74 | F28: =F26+F18 -> 937.27115 | G28: =G26+G18 -> 1245 | H28: =H26+H18 -> 1235 | I28: =I26+I18 -> 1245 | J28: =J26+J18 -> 1265 | ... O28: =O26+O18 -> 1775
B30: EXPENSES | C30: TOTALS | D30: JAN | E30: FEB | F30: MAR | G30: APR | H30: MAY | I30: JUN | J30: JUL | K30: AUG | L30: SEP | M30: OCT | N30: NOV | O30: DEC
B31: Maintenance | C31: =SUM(D31:O31) -> 375 | D31: 0 | E31: 0 | F31: 0 | G31: 0 | H31: 0 | I31: 0 | J31: 0 | K31: 0 | L31: =Expenditure!E88 -> 15 | M31: 0 | N31: 0 | O31: =Expenditure!E120 -> 360
B32: Utilities | C32: =SUM(D32:O32) -> 55 | D32: =Expenditure!E10 -> 10 | E32: 0 | F32: 0 | G32: 0 | H32: 0 | I32: 0 | J32: =Expenditure!E72 -> 10 | K32: 0 | L32: =Expenditure!E90 -> 15 | M32: 0 | N32: 0 | O32: =Expenditure!E121 -> 20
B33: Wages & salaries | C33: =SUM(D33:O33) -> 1960 | D33: =Expenditure!E6 -> 100 | E33: =Expenditure!E18+Expenditure!E19 -> 120 | F33: =Expenditure!E28 -> 100 | G33: =Expenditure!E39 -> 140 | H33: =Expenditure!E50 -> 140 | I33: =Expenditure!E59 -> 140 | J33: =Expenditure!E70+Expenditure!E71 -> 220 | K33: =Expenditure!E79 -> 200 | L33: =Expenditure!E89 -> 200 | M33: =Expenditure!E100 -> 200 | N33: =Expenditure!E109 -> 200 | O33: =Expenditure!E119 -> 200
B34: Repairs | C34: =SUM(D34:O34) -> 937 | D34: =Expenditure!E7+Expenditure!E9 -> 64 | E34: 0 | F34: 0 | G34: 0 | H34: =Expenditure!E51+Expenditure!E49 -> 90 | I34: 0 | J34: =Expenditure!E69 -> 475 | K34: =Expenditure!E80 -> 285 | L34: 0 | M34: =Expenditure!E99 -> 23 | N34: 0 | O34: 0
B35: Property taxes | C35: =SUM(D35:O35) -> 250 | D35: 0 | E35: 0 | F35: =Expenditure!E29 -> 250 | G35: 0 | H35: 0 | I35: 0 | J35: 0 | K35: 0 | L35: 0 | M35: 0 | N35: 0 | O35: 0
B36: Other | C36: =SUM(D36:O36) -> 158 | D36: =Expenditure!E8 -> 28 | E36: 0 | F36: 0 | G36: 0 | H36: 0 | I36: =Expenditure!E60 -> 130 | J36: 0 | K36: 0 | L36: 0 | M36: 0 | N36: 0 | O36: 0
B37: TOTAL EXPENSES | C37: =SUM(C31:C36) -> 3735 | D37: =SUM(D31:D36) -> 202 | E37: =SUM(E31:E36) -> 120 | F37: =SUM(F31:F36) -> 350 | G37: =SUM(G31:G36) -> 140 | H37: =SUM(H31:H36) -> 230 | I37: =SUM(I31:I36) -> 270 | J37: =SUM(J31:J36) -> 705 | ... O37: =SUM(O31:O36) -> 580
B39: NET OPERATING INCOME | C39: =C28-C37 -> 14715.541 | D39: =D28-D37 -> 729.53 | E39: =E28-E37 -> 786.74 | F39: =F28-F37 -> 587.27115 | G39: =G28-G37 -> 1105 | H39: =H28-H37 -> 1005 | I39: =I28-I37 -> 975 | J39: =J28-J37 -> 560 | ... O39: =O28-O37 -> 1195
C41: TOTALS | D41: =D30 -> JAN | E41: =E30 -> FEB | F41: =F30 -> MAR | G41: =G30 -> APR | H41: =H30 -> MAY | I41: =I30 -> JUN | J41: =J30 -> JUL | K41: =K30 -> AUG | ... O41: =O30 -> DEC
B42: Loan repayment withdrawals | C42: =SUM(D42:O42) -> 12515 | D42: =Expenditure!E11 -> 729 | E42: =Expenditure!E20 -> 787 | F42: =Expenditure!E30 -> 587 | G42: =Expenditure!E40 -> 1105 | H42: =Expenditure!E52 -> 1005 | I42: =Expenditure!E61 -> 975 | J42: =Expenditure!E73 -> 560 | K42: =Expenditure!E81 -> 1240 | L42: =Expenditure!E91 -> 1350 | M42: =Expenditure!E101 -> 1607 | N42: =Expenditure!E110 -> 1375 | O42: =Expenditure!E122 -> 1195
B43: Total loan repayment | C43: =SUM(C42) -> 12515 | D43: =SUM(D42) -> 729 | E43: =SUM(E42) -> 787 | F43: =SUM(F42) -> 587 | G43: =SUM(G42) -> 1105 | H43: =SUM(H42) -> 1005 | I43: =SUM(I42) -> 975 | J43: =SUM(J42) -> 560 | ... O43: =SUM(O42) -> 1195
B45: NET CASH FLOW | C45: =C39-C43 -> 2200.5412 | D45: =D39-D43 -> 0.53 | E45: =E39-E43 -> -0.26 | F45: =F39-F43 -> 0.27115385 | G45: =G39-G43 -> 0 | H45: =H39-H43 -> 0 | I45: =I39-I43 -> 0 | J45: =J39-J43 -> 0 | ... O45: =O39-O43 -> 0

Sheet Tenant movement schedule

Sheet Withdrawals recon
C2: January | D2: February | E2: March | F2: April | G2: May | H2: June | I2: July | J2: August | K2: September | L2: October | M2: November | N2: December | O2: Total
B3: Withdrawals | C3: ='Income vs Expenditure'!D42 -> 729 | D3: ='Income vs Expenditure'!E42 -> 787 | E3: ='Income vs Expenditure'!F42 -> 587 | F3: ='Income vs Expenditure'!G42 -> 1105 | G3: ='Income vs Expenditure'!H42 -> 1005 | H3: ='Income vs Expenditure'!I42 -> 975 | I3: ='Income vs Expenditure'!J42 -> 560 | J3: ='Income vs Expenditure'!K42 -> 1240 | ... N3: ='Income vs Expenditure'!O42 -> 1195 | O3: =SUM(C3:N3) -> 12515
B5: Econet | C5: 50 | D5: 50 | E5: 50 | F5: 50 | G5: 50 | H5: 50 | I5: 50 | J5: 50 | K5: 50 | L5: 50 | M5: 50 | N5: 50 | O5: =SUM(C5:N5) -> 600
B6: Edgars | H6: 20 | I6: 20 | J6: 20 | K6: 20 | L6: 20 | M6: 20 | N6: 20 | O6: =SUM(C6:N6) -> 140
B7: Electricity | C7: 50 | D7: 50 | E7: 50 | F7: 50 | G7: 50 | H7: 50 | I7: 60 | K7: 60 | L7: 50 | M7: 60 | N7: 60 | O7: =SUM(C7:N7) -> 590
B8: Gas | C8: 72 | O8: =SUM(C8:N8) -> 72
B9: DSTV | K9: 91 | L9: 91 | M9: 91 | N9: 91 | O9: =SUM(C9:N9) -> 364
B10: Medical Aid (First Mutual) | C10: 106 | D10: 106 | E10: 106 | F10: 40 | G10: 39 | H10: 33 | I10: 104 | J10: 106 | O10: =SUM(C10:N10) -> 640
B11: ZOL | C11: 80 | D11: 80 | E11: 80 | F11: 80 | G11: 80 | H11: 80 | I11: 150 | J11: 150 | K11: 112 | L11: 115 | M11: 125 | N11: 125 | O11: =SUM(C11:N11) -> 1257
B12: Fuel | O12: =SUM(C12:N12) -> 0
B13: Mai Tino | C13: 150 | D13: 150 | E13: 150 | F13: 150 | G13: 150 | H13: 200 | I13: 200 | J13: 150 | K13: 150 | L13: 170 | M13: 150 | N13: 150 | O13: =SUM(C13:N13) -> 1920
B14: Aunty Precious | C14: 130 | D14: 100 | E14: 100 | F14: 100 | G14: 100 | H14: 100 | I14: 100 | J14: 100 | K14: 100 | L14: 110 | M14: 100 | N14: 100 | O14: =SUM(C14:N14) -> 1240
B15: Sherphard | C15: 50 | D15: 50 | E15: 50 | L15: 110 | O15: =SUM(C15:N15) -> 260
B16: Thumelo Boarding Fees | L16: 120 | M16: 125 | N16: 88 | O16: =SUM(C16:N16) -> 333
B17: Groceries and Perishables | O17: =SUM(C17:N17) -> 0
B18: Building | O18: =SUM(C18:N18) -> 0
B20: Total expenses | C20: =SUM(C5:C18) -> 688 | D20: =SUM(D5:D18) -> 586 | E20: =SUM(E5:E18) -> 586 | F20: =SUM(F5:F18) -> 470 | G20: =SUM(G5:G18) -> 469 | H20: =SUM(H5:H18) -> 533 | I20: =SUM(I5:I18) -> 684 | J20: =SUM(J5:J18) -> 576 | ... N20: =SUM(N5:N18) -> 684 | O20: =SUM(C20:N20) -> 7416
B21: Unaaccounted amounts | C21: =C3-C20 -> 41 | D21: =D3-D20 -> 201 | E21: =E3-E20 -> 1 | F21: =F3-F20 -> 635 | G21: =G3-G20 -> 536 | H21: =H3-H20 -> 442 | I21: =I3-I20 -> -124 | J21: =J3-J20 -> 664 | ... N21: =N3-N20 -> 511 | O21: =SUM(C21:N21) -> 5099
E22: `
B23: will come back to this
